Workbook
Name Business_Location: 'Model Guide'!$E$10
Name Company_Name: 'Model Guide'!$E$9
Name coy_name: 'Cover Page'!$E$3
Name Ctrl_1: 'Model Guide'!$E$75
Name Ctrl_10: 'Model Guide'!$E$84
Name Ctrl_11: 'Model Guide'!$E$85
Name Ctrl_12: 'Model Guide'!$E$86
Name Ctrl_2: 'Model Guide'!$E$76
Name Ctrl_3: 'Model Guide'!$E$77
Name Ctrl_4: 'Model Guide'!$E$78
Name Ctrl_5: 'Model Guide'!$E$79
Name Ctrl_6: 'Model Guide'!$E$80
Name Ctrl_7: 'Model Guide'!$E$81
Name Ctrl_8: 'Model Guide'!$E$82
Name Ctrl_9: 'Model Guide'!$E$83
Name Days_in_a_Year: 'Model Guide'!$E$34
Name Divisor: 'Model Guide'!$E$44
Name Industry: 'Model Guide'!$E$11
Name List: Scenerio!$E$11:$E$13
Name Model_Forecasting_Period: 'Model Guide'!$E$36
Name Model_Period_End: 'Model Guide'!$E$37
Name Model_Period_Start: 'Model Guide'!$E$35
Name Months_in_a_period: 'Model Guide'!$E$33
Name Purpose_of_the_Model: 'Model Guide'!$E$12
Name switch: Scenerio!$F$10

Sheet Logo

Sheet Cover Page
C3: Company | E3: Tage Corp
C4: Business Industry | E4: =Industry -> Fashion
C5: Business Location | E5: =Business_Location -> Nigeria
C7: Business Description
B12: Table of Content
C13: Inputs & Calculation
D14: Inputs/Assumption
D15: Calculation
C17: Output & Analysis
D18: Income Statement
D19: Balance Sheet
D20: Cashflow Statement
D21: Analysis
D22: DCF Valuation

Sheet Model Guide
B1: Tage Corp
B2: Guide
B6: Model Details
C8: Company Information
D9: Company Name | E9: Tage Corp
D10: Location | E10: Nigeria
D11: Industry | E11: Fashion
D12: Purpose of the Model | E12: Investment Committee
B14: Model Information
D15: Model Owner | E15: Tage
D16: Currency | E16: Naira (₦)
D17: Current Modeler | E17: Fafiola Oluwatimilehin
D18: Modeler's Contact | E18: +234-XXX-XXX'
B20: Model Structure & Navigation
C21: Sheet Structure
D22: Cover Page
D23: Guide
D24: Input
D25: Calculator
D26: Income Statement
D27: Balance Sheet
D28: Cash Flow Satement
D29: Analysis
D30: Valuation
C32: Major Timing
D33: Months in a period | E33: 12
D34: Days in a Year | E34: 365
D35: Model Period Start | E35: 45658
D36: Model Forecasting Period | E36: 5
D37: Model Period End | E37: =EDATE(E35-1,(E33*E36)) -> 47483
C39: Model Style Guide
D40: Normal Cell | E40: 1234
D41: Input Cell | E41: 12345
D42: Formula Cell | E42: 12345
D43: Linked Cell | E43: 12345
D44: Divisor | E44: 1000
D45: Percentage | E45: 0.3
E46: 30
D47: Total | E47: 12345
D48: Subtotal | E48: 12345
...

Sheet Input
B2: =Company_Name -> Tage Corp | N2: Menu
C3: ='Model Guide'!D24 -> Input
D4: Model Scenerio
D5: Model Balance Check | H5: Start Date | J5: =I6+Ctrl_1 -> 45658 | K5: =J6+Ctrl_1 -> 46023 | L5: =K6+Ctrl_1 -> 46388 | M5: =L6+Ctrl_1 -> 46753 | N5: =M6+Ctrl_1 -> 47119
H6: End Date | I6: =EOMONTH(J6,- Ctrl_12) -> 45657 | J6: =EOMONTH(K6,- Ctrl_12) -> 46022 | K6: =EOMONTH(L6,- Ctrl_12) -> 46387 | L6: =EOMONTH(M6,- Ctrl_12) -> 46752 | M6: =EOMONTH(N6,- Ctrl_12) -> 47118 | N6: =Model_Period_End -> 47483
H7: Year | I7: =YEAR(I6) -> 2024 | J7: =YEAR(J6) -> 2025 | K7: =YEAR(K6) -> 2026 | L7: =YEAR(L6) -> 2027 | M7: =YEAR(M6) -> 2028 | N7: =YEAR(N6) -> 2029
D8: Descriptions | E8: Units | F8: Inputs/Linked | H8: Row Total | I8: Forecast | J8: Forecast | K8: Forecast | L8: Forecast | M8: Forecast | N8: Forecast
I9: =I7-$I$7 -> 0 | J9: =J7-$I$7 -> 1 | K9: =K7-$I$7 -> 2 | L9: =L7-$I$7 -> 3 | M9: =M7-$I$7 -> 4 | N9: =N7-$I$7 -> 5
B11: General & Macro-economic
C12: Assumptions
D13: Timing
D14: Counter | J14: =I14+1 -> 1 | K14: =J14+1 -> 2 | L14: =K14+1 -> 3 | M14: =L14+1 -> 4 | N14: =M14+1 -> 5
D16: Inflation
D17: Inflation rate | E17: [%] | G17: make changes from the scenario | J17: =Scenerio!J16 -> 0.3003 | K17: =Scenerio!K16 -> 0.2503 | L17: =Scenerio!L16 -> 0.2 | M17: =Scenerio!M16 -> 0.1 | N17: =Scenerio!N16 -> 0.1
D18: Inflation index | J18: =(1+J17)^(J14-1) -> 1 | K18: =(1+K17)^(K14-1) -> 1.2503 | L18: =(1+L17)^(L14-1) -> 1.44 | M18: =(1+M17)^(M14-1) -> 1.331 | N18: =(1+N17)^(N14-1) -> 1.4641
D20: Pricing Growth
D21: Pricing growth rate | E21: [%] | J21: 0.012 | K21: 0.017 | L21: 0.018 | M21: 0.02 | N21: 0.02
D22: Pricing index | J22: =(1+J21)^(J14-1) -> 1 | K22: =(1+K21)^(K14-1) -> 1.017 | L22: =(1+L21)^(L14-1) -> 1.036324 | M22: =(1+M21)^(M14-1) -> 1.061208 | N22: =(1+N21)^(N14-1) -> 1.0824322
D24: Quantity Growth
D25: Quantity growth rate | E25: [%] | G25: make changes from the scenario | J25: =Scenerio!J22 -> 0.0713 | K25: =Scenerio!K22 -> 0.0713 | L25: =Scenerio!L22 -> 0.0713 | M25: =Scenerio!M22 -> 0.0713 | N25: =Scenerio!N22 -> 0.0713
D27: Government
D28: Provision for tax rate | E28: [%] | F28: 0.2
D30: Assets
D31: Assets depreciation | E31: [years] | F31: 5
D32: Assets maintenance | J32: 0 | K32: 0.5 | L32: 0.5 | M32: 1.5 | N32: 1.5
B34: Funding & Use of funds
C35: Funding
D36: Sources of Funds
D37: Loan | E37: [₦] | J37: 8000000
D38: Equity | E38: [₦] | J38: 12000000
D39: Total funding | E39: [₦] | J39: =SUM(J37,J38) -> 20000000
D41: Cost of Financing - Loan
D42: Loan period | E42: [years] | F42: 3
D43: Interest rate | E43: [%] | F43: 0.27
D45: Cost of fnancing - equity
D46: Dividend payout ratio | E46: [%] | F46: 0.15
D47: Discounting rate | E47: [%]
C49: Use of Funds
D50: Business development
D51: Production equipment & machinery | E51: [₦] | J51: 4000000 | K51: 200000 | L51: 150000 | M51: 100000 | N51: 75000
...

Sheet Cal
J1: Do not Change Any Value in Linked Cells. Do that in the Input Sheet
B2: =Company_Name -> Tage Corp | N2: Menu
C3: ='Model Guide'!D25 -> Calculator
D4: Model Scenerio
D5: Model Balance Check | H5: Start Date | J5: =I6+Ctrl_1 -> 45658 | K5: =J6+Ctrl_1 -> 46023 | L5: =K6+Ctrl_1 -> 46388 | M5: =L6+Ctrl_1 -> 46753 | N5: =M6+Ctrl_1 -> 47119
H6: End Date | I6: =EOMONTH(J6,- Ctrl_12) -> 45657 | J6: =EOMONTH(K6,- Ctrl_12) -> 46022 | K6: =EOMONTH(L6,- Ctrl_12) -> 46387 | L6: =EOMONTH(M6,- Ctrl_12) -> 46752 | M6: =EOMONTH(N6,- Ctrl_12) -> 47118 | N6: =Model_Period_End -> 47483
H7: Year | I7: =YEAR(I6) -> 2024 | J7: =YEAR(J6) -> 2025 | K7: =YEAR(K6) -> 2026 | L7: =YEAR(L6) -> 2027 | M7: =YEAR(M6) -> 2028 | N7: =YEAR(N6) -> 2029
D8: Descriptions | E8: Unit | F8: Input/Linked | H8: Row Total | I8: Forecast | J8: Forecast | K8: Forecast | L8: Forecast | M8: Forecast | N8: Forecast
I9: =I7-$I$7 -> 0 | J9: =J7-$I$7 -> 1 | K9: =K7-$I$7 -> 2 | L9: =L7-$I$7 -> 3 | M9: =M7-$I$7 -> 4 | N9: =N7-$I$7 -> 5
B11: Operations Calculation
C12: Revenue & Cost of Sales
D13: Pricing index | J13: =Input!J22 -> 1 | K13: =Input!K22 -> 1.017 | L13: =Input!L22 -> 1.036324 | M13: =Input!M22 -> 1.061208 | N13: =Input!N22 -> 1.0824322
D14: Inflation index | J14: =Input!J18 -> 1 | K14: =Input!K18 -> 1.2503 | L14: =Input!L18 -> 1.44 | M14: =Input!M18 -> 1.331 | N14: =Input!N18 -> 1.4641
D15: Months in a period | J15: =Months_in_a_period -> 12 | K15: =Months_in_a_period -> 12 | L15: =Months_in_a_period -> 12 | M15: =Months_in_a_period -> 12 | N15: =Months_in_a_period -> 12
D16: Quantity growth rate | E16: [%] | J16: =Input!J25 -> 0.0713 | K16: =Input!K25 -> 0.0713 | L16: =Input!L25 -> 0.0713 | M16: =Input!M25 -> 0.0713 | N16: =Input!N25 -> 0.0713
D18: Product Pricing
D19: Ready-to-wear dresses | E19: [₦] | I19: =Input!F65 -> 50000 | J19: =I19*J13 -> 50000 | K19: =J19*K13 -> 50850 | L19: =K19*L13 -> 52697.075 | M19: =L19*M13 -> 55922.558 | N19: =M19*N13 -> 60532.375
D20: Custom-made outfits | E20: [₦] | I20: =Input!F66 -> 80000 | J20: =I20*J13 -> 80000 | K20: =J20*K13 -> 81360 | L20: =K20*L13 -> 84315.321 | M20: =L20*M13 -> 89476.093 | N20: =M20*N13 -> 96851.8
D21: Accessories (bags/scarves) | E21: [₦] | I21: =Input!F67 -> 25000 | J21: =I21*J13 -> 25000 | K21: =J21*K13 -> 25425 | L21: =K21*L13 -> 26348.538 | M21: =L21*M13 -> 27961.279 | N21: =M21*N13 -> 30266.188
D23: Product Cost
D24: Ready-to-wear dresses | E24: [₦] | I24: =Input!F70 -> 15000 | J24: =I24*J14 -> 15000 | K24: =J24*K14 -> 18754.5 | L24: =K24*L14 -> 27006.48 | M24: =L24*M14 -> 35945.625 | N24: =M24*N14 -> 52627.989
D25: Custom-made outfits | E25: [₦] | I25: =Input!F71 -> 26000 | J25: =I25*J14 -> 26000 | K25: =J25*K14 -> 32507.8 | L25: =K25*L14 -> 46811.232 | M25: =L25*M14 -> 62305.75 | N25: =M25*N14 -> 91221.848
D26: Accessories (bags/scarves) | E26: [₦] | I26: =Input!F72 -> 5000 | J26: =I26*J14 -> 5000 | K26: =J26*K14 -> 6251.5 | L26: =K26*L14 -> 9002.16 | M26: =L26*M14 -> 11981.875 | N26: =M26*N14 -> 17542.663
D28: Product Quantity
D29: Ready-to-wear dresses | E29: [unit] | F29: =Input!F75 -> 90 | I29: =F29*J15 -> 1080 | J29: =I29*(1+J16) -> 1157.004 | K29: =J29*(1+K16) -> 1239.4984 | L29: =K29*(1+L16) -> 1327.8746 | M29: =L29*(1+M16) -> 1422.5521 | N29: =M29*(1+N16) -> 1523.98
D30: Custom-made outfits | E30: [unit] | F30: =Input!F76 -> 50 | I30: =F30*J15 -> 600 | J30: =I30*(1+J16) -> 642.78 | K30: =J30*(1+K16) -> 688.61021 | L30: =K30*(1+L16) -> 737.70812 | M30: =L30*(1+M16) -> 790.30671 | N30: =M30*(1+N16) -> 846.65558
D31: Accessories (bags/scarves) | E31: [unit] | F31: =Input!F77 -> 85 | I31: =F31*J15 -> 1020 | J31: =I31*(1+J16) -> 1092.726 | K31: =J31*(1+K16) -> 1170.6374 | L31: =K31*(1+L16) -> 1254.1038 | M31: =L31*(1+M16) -> 1343.5214 | N31: =M31*(1+N16) -> 1439.3145
D34: Revenue
D35: Ready-to-wear dresses | E35: [₦] | J35: =I29*J19 -> 54000000 | K35: =J29*K19 -> 58833653 | L35: =K29*L19 -> 65317940 | M35: =L29*M19 -> 74258145 | N35: =M29*N19 -> 86110456
D36: Custom-made outfits | E36: [₦] | J36: =I30*J20 -> 48000000 | K36: =J30*K20 -> 52296581 | L36: =K30*L20 -> 58060391 | M36: =L30*M20 -> 66007240 | N36: =M30*N20 -> 76542628
D37: Accessories (bags/scarves) | E37: [₦] | J37: =I31*J21 -> 25500000 | K37: =J31*K21 -> 27782559 | L37: =K31*L21 -> 30844583 | M37: =L31*M21 -> 35066346 | N37: =M31*N21 -> 40663271
D38: Total revenue | E38: [₦] | J38: =SUM(J35:J37) -> 127500000 | K38: =SUM(K35:K37) -> 1.3891279e+08 | L38: =SUM(L35:L37) -> 1.5422291e+08 | M38: =SUM(M35:M37) -> 1.7533173e+08 | N38: =SUM(N35:N37) -> 2.0331636e+08
D40: Cost of sales
D41: Ready-to-wear dresses | E41: [₦] | J41: =I29*I24 -> 16200000 | K41: =J29*J24 -> 17355060 | L41: =K29*K24 -> 23246172 | M41: =L29*L24 -> 35861219 | N41: =M29*M24 -> 51134523
D42: Custom-made outfits | E42: [₦] | J42: =I30*I25 -> 15600000 | K42: =J30*J25 -> 16712280 | L42: =K30*K25 -> 22385203 | M42: =L30*L25 -> 34533026 | N42: =M30*M25 -> 49240652
D43: Accessories (bags/scarves) | E43: [₦] | J43: =I31*I26 -> 5100000 | K43: =J31*J26 -> 5463630 | L43: =K31*K26 -> 7318239.5 | M43: =L31*L26 -> 11289643 | N43: =M31*M26 -> 16097906
D44: Cost of Sales | E44: [₦] | J44: =SUM(J41:J43) -> 36900000 | K44: =SUM(K41:K43) -> 39530970 | L44: =SUM(L41:L43) -> 52949615 | M44: =SUM(M41:M43) -> 81683889 | N44: =SUM(N41:N43) -> 1.1647308e+08
B48: Selling, General & Admin Expenses
C49: Months in a period | J49: =Months_in_a_period -> 12 | K49: =Months_in_a_period -> 12 | L49: =Months_in_a_period -> 12 | M49: =Months_in_a_period -> 12 | N49: =Months_in_a_period -> 12
C50: Inflation index | J50: =Input!J18 -> 1 | K50: =Input!K18 -> 1.2503 | L50: =Input!L18 -> 1.44 | M50: =Input!M18 -> 1.331 | N50: =Input!N18 -> 1.4641
...

Sheet IS
B2: =Company_Name -> Tage Corp | N2: Menu
C3: ='Model Guide'!D26 -> Income Statement
D4: Model Scenerio
D5: Model Balance Check | H5: Start Date | J5: =I6+Ctrl_1 -> 45658 | K5: =J6+Ctrl_1 -> 46023 | L5: =K6+Ctrl_1 -> 46388 | M5: =L6+Ctrl_1 -> 46753 | N5: =M6+Ctrl_1 -> 47119
H6: End Date | I6: =EOMONTH(J6,- Ctrl_12) -> 45657 | J6: =EOMONTH(K6,- Ctrl_12) -> 46022 | K6: =EOMONTH(L6,- Ctrl_12) -> 46387 | L6: =EOMONTH(M6,- Ctrl_12) -> 46752 | M6: =EOMONTH(N6,- Ctrl_12) -> 47118 | N6: =Model_Period_End -> 47483
H7: Year | I7: =YEAR(I6) -> 2024 | J7: =YEAR(J6) -> 2025 | K7: =YEAR(K6) -> 2026 | L7: =YEAR(L6) -> 2027 | M7: =YEAR(M6) -> 2028 | N7: =YEAR(N6) -> 2029
D8: Descriptions | E8: Units | F8: Input/Linked | H8: Row Total | I8: Forecast | J8: Forecast | K8: Forecast | L8: Forecast | M8: Forecast | N8: Forecast
I9: =I7-$I$7 -> 0 | J9: =J7-$I$7 -> 1 | K9: =K7-$I$7 -> 2 | L9: =L7-$I$7 -> 3 | M9: =M7-$I$7 -> 4 | N9: =N7-$I$7 -> 5
D10: Revenue | E10: [₦'000] | J10: =Cal!J38/Divisor -> 127500 | K10: =Cal!K38/Divisor -> 138912.79 | L10: =Cal!L38/Divisor -> 154222.91 | M10: =Cal!M38/Divisor -> 175331.73 | N10: =Cal!N38/Divisor -> 203316.36
D11: Cost of Sales | E11: [₦'000] | J11: =Cal!J44/Divisor -> 36900 | K11: =Cal!K44/Divisor -> 39530.97 | L11: =Cal!L44/Divisor -> 52949.615 | M11: =Cal!M44/Divisor -> 81683.889 | N11: =Cal!N44/Divisor -> 116473.08
D12: Gross Profit | E12: [₦'000] | J12: =J10-J11 -> 90600 | K12: =K10-K11 -> 99381.823 | L12: =L10-L11 -> 101273.3 | M12: =M10-M11 -> 93647.844 | N12: =N10-N11 -> 86843.274
D13: gross margin | E13: [%] | J13: =J12/J10 -> 0.71058824 | K13: =K12/K10 -> 0.71542599 | L13: =L12/L10 -> 0.6566683 | M13: =M12/M10 -> 0.53411805 | N13: =N12/N10 -> 0.42713373
D14: SG&A | E14: [₦'000] | J14: =Cal!J98/Divisor -> 26480 | K14: =Cal!K98/Divisor -> 18829.374 | L14: =Cal!L98/Divisor -> 21445.2 | M14: =Cal!M98/Divisor -> 19755.98 | N14: =Cal!N98/Divisor -> 21546.578
D15: EBITDA | E15: [₦'000] | J15: =J12-J14 -> 64120 | K15: =K12-K14 -> 80552.449 | L15: =L12-L14 -> 79828.099 | M15: =M12-M14 -> 73891.864 | N15: =N12-N14 -> 65296.696
D16: ebitda margin | E16: [%] | J16: =J15/J10 -> 0.50290196 | K16: =K15/K10 -> 0.57987783 | L16: =L15/L10 -> 0.51761503 | M16: =M15/M10 -> 0.42144033 | N16: =N15/N10 -> 0.32115811
D17: Depriciation | E17: [₦'000] | J17: =Cal!J170/Divisor -> 1500 | K17: =Cal!K170/Divisor -> 1770 | L17: =Cal!L170/Divisor -> 2037 | M17: =Cal!M170/Divisor -> 2718.1 | N17: =Cal!N170/Divisor -> 3573.53
D18: EBIT | E18: [₦'000] | J18: =J15-J17 -> 62620 | K18: =K15-K17 -> 78782.449 | L18: =L15-L17 -> 77791.099 | M18: =M15-M17 -> 71173.764 | N18: =N15-N17 -> 61723.166
D19: Interest Expense | E19: [₦'000] | J19: =Cal!J140/Divisor -> 1080 | K19: =Cal!K140/Divisor -> 656.05737 | L19: =Cal!L140/Divisor -> 174.88249 | M19: =Cal!M140/Divisor -> 0 | N19: =Cal!N140/Divisor -> 0
D20: Profit before tax | E20: [₦'000] | J20: =J18-J19 -> 61540 | K20: =K18-K19 -> 78126.391 | L20: =L18-L19 -> 77616.216 | M20: =M18-M19 -> 71173.764 | N20: =N18-N19 -> 61723.166
D21: Tax Expense | E21: [₦'000] | J21: =(J20>0)*(J20*Input!$F$28) -> 12308 | K21: =(K20>0)*(K20*Input!$F$28) -> 15625.278 | L21: =(L20>0)*(L20*Input!$F$28) -> 15523.243 | M21: =(M20>0)*(M20*Input!$F$28) -> 14234.753 | N21: =(N20>0)*(N20*Input!$F$28) -> 12344.633
D22: Profit before the Period | E22: [₦'000] | J22: =J20-J21 -> 49232 | K22: =K20-K21 -> 62501.113 | L22: =L20-L21 -> 62092.973 | M22: =M20-M21 -> 56939.011 | N22: =N20-N21 -> 49378.533
D23: net profit margin | E23: [%] | J23: =J22/J10 -> 0.38613333 | K23: =K22/K10 -> 0.44993058 | L23: =L22/L10 -> 0.40261834 | M23: =M22/M10 -> 0.32475018 | N23: =N22/N10 -> 0.24286552

Sheet CF
B2: =Company_Name -> Tage Corp | N2: Menu
C3: ='Model Guide'!D28 -> Cash Flow Satement
D4: Model Scenerio
D5: Model Balance Check | H5: Start Date | J5: =I6+Ctrl_1 -> 45658 | K5: =J6+Ctrl_1 -> 46023 | L5: =K6+Ctrl_1 -> 46388 | M5: =L6+Ctrl_1 -> 46753 | N5: =M6+Ctrl_1 -> 47119
H6: End Date | I6: =EOMONTH(J6,- Ctrl_12) -> 45657 | J6: =EOMONTH(K6,- Ctrl_12) -> 46022 | K6: =EOMONTH(L6,- Ctrl_12) -> 46387 | L6: =EOMONTH(M6,- Ctrl_12) -> 46752 | M6: =EOMONTH(N6,- Ctrl_12) -> 47118 | N6: =Model_Period_End -> 47483
H7: Year | I7: =YEAR(I6) -> 2024 | J7: =YEAR(J6) -> 2025 | K7: =YEAR(K6) -> 2026 | L7: =YEAR(L6) -> 2027 | M7: =YEAR(M6) -> 2028 | N7: =YEAR(N6) -> 2029
D8: Descriptions | E8: Units | F8: Input/Linked | H8: Row Total | I8: Forecast | J8: Forecast | K8: Forecast | L8: Forecast | M8: Forecast | N8: Forecast
I9: =I7-$I$7 -> 0 | J9: =J7-$I$7 -> 1 | K9: =K7-$I$7 -> 2 | L9: =L7-$I$7 -> 3 | M9: =M7-$I$7 -> 4 | N9: =N7-$I$7 -> 5
C10: Cash Flow from Operating Activities (CFFO)
D11: Profit Before Tax | E11: [₦ 0'000] | J11: =IS!J20 -> 61540 | K11: =IS!K20 -> 78126.391 | L11: =IS!L20 -> 77616.216 | M11: =IS!M20 -> 71173.764 | N11: =IS!N20 -> 61723.166
D12: adjustment for non-cash
D13: Depriciation & amort. | E13: [₦ 0'000] | J13: =IS!J17 -> 1500 | K13: =IS!K17 -> 1770 | L13: =IS!L17 -> 2037 | M13: =IS!M17 -> 2718.1 | N13: =IS!N17 -> 3573.53
D14: Changes in OWC
D15: Inventories | E15: [₦ 0'000] | J15: =BS!I16-BS!J16 -> -5054.7945 | K15: =BS!J16-BS!K16 -> -360.40685 | L15: =BS!K16-BS!L16 -> -1838.1706 | M15: =BS!L16-BS!M16 -> -3905.6292 | N15: =BS!M16-BS!N16 -> -4796.2154
D16: Trade Recievables | E16: [₦ 0'000] | J16: =BS!I17-BS!J17 -> -13972.603 | K16: =BS!J17-BS!K17 -> -1250.717 | L16: =BS!K17-BS!L17 -> -1677.8215 | M16: =BS!L17-BS!M17 -> -2260.7967 | N16: =BS!M17-BS!N17 -> -3119.3065
D17: Prepayment | E17: [₦ 0'000] | J17: =BS!I18-BS!J18 -> -1088.2192 | K17: =BS!J18-BS!K18 -> 314.40929 | L17: =BS!K18-BS!L18 -> -107.4997 | M17: =BS!L18-BS!M18 -> 71.638278 | N17: =BS!M18-BS!N18 -> -75.804497
D18: Trade Payables | E18: [₦ 0'000] | J18: =BS!J27-BS!I27 -> 4043.8356 | K18: =BS!K27-BS!J27 -> 288.32548 | L18: =BS!L27-BS!K27 -> 1470.5364 | M18: =BS!M27-BS!L27 -> 3124.5034 | N18: =BS!N27-BS!M27 -> 3836.9723
D19: Accurals & Other Liabilities | E19: [₦ 0'000] | J19: =BS!J28-BS!I28 -> 1450.9589 | K19: =BS!K28-BS!J28 -> -419.21238 | L19: =BS!L28-BS!K28 -> 143.33293 | M19: =BS!M28-BS!L28 -> -95.517703 | N19: =BS!N28-BS!M28 -> 101.07266
D20: Taxation
D21: Tax Paid | E21: [₦ 0'000] | J21: =-IS!J21 -> -12308 | K21: =-IS!K21 -> -15625.278 | L21: =-IS!L21 -> -15523.243 | M21: =-IS!M21 -> -14234.753 | N21: =-IS!N21 -> -12344.633
D22: Net CFFO | E22: [₦ 0'000] | J22: =SUM(J11:J21) -> 36111.178 | K22: =SUM(K11:K21) -> 62843.512 | L22: =SUM(L11:L21) -> 62120.35 | M22: =SUM(M11:M21) -> 56591.309 | N22: =SUM(N11:N21) -> 48898.781
C23: Cash Flow from Investing Activities (CFFI)
D24: PPE | E24: [₦ 0'000] | J24: =-Cal!J169/Divisor -> -7500 | K24: =-Cal!K169/Divisor -> -1350 | L24: =-Cal!L169/Divisor -> -1335 | M24: =-Cal!M169/Divisor -> -3405.5 | N24: =-Cal!N169/Divisor -> -4277.15
D25: Net CFFI | E25: [₦ 0'000] | J25: =SUM(J24) -> -7500 | K25: =SUM(K24) -> -1350 | L25: =SUM(L24) -> -1335 | M25: =SUM(M24) -> -3405.5 | N25: =SUM(N24) -> -4277.15
C26: Cash Flow from Financing Activities (CFFF)
D27: Equity new Issue | E27: [₦ 0'000] | J27: =Cal!J147/Divisor -> 12000 | K27: =Cal!K147/Divisor -> 0 | L27: =Cal!L147/Divisor -> 0 | M27: =Cal!M147/Divisor -> 0 | N27: =Cal!N147/Divisor -> 0
D28: Long Term Loans | E28: [₦ 0'000] | J28: =Cal!J136/Divisor -> 8000 | K28: =Cal!K136/Divisor -> 0 | L28: =Cal!L136/Divisor -> 0 | M28: =Cal!M136/Divisor -> 0 | N28: =Cal!N136/Divisor -> 0
D29: Dividends | E29: [₦ 0'000] | J29: =-Cal!J155/Divisor -> -13292.64 | K29: =-Cal!K155/Divisor -> -16875.301 | L29: =-Cal!L155/Divisor -> -16765.103 | M29: =-Cal!M155/Divisor -> -15373.533 | N29: =-Cal!N155/Divisor -> -13332.204
D30: Principal Repayment | E30: [₦ 0'000] | J30: =-Cal!J137/Divisor -> -3140.3157 | K30: =-Cal!K137/Divisor -> -3564.2584 | L30: =-Cal!L137/Divisor -> -1295.4259 | M30: =-Cal!M137/Divisor -> 0 | N30: =-Cal!N137/Divisor -> 0
D31: Net CFFF | E31: [₦ 0'000] | J31: =SUM(J27:J30) -> 3567.0443 | K31: =SUM(K27:K30) -> -20439.559 | L31: =SUM(L27:L30) -> -18060.529 | M31: =SUM(M27:M30) -> -15373.533 | N31: =SUM(N27:N30) -> -13332.204
C32: Cash Schedule
D33: Beginning Balance | E33: [₦ 0'000] | J33: =I35 -> 0 | K33: =J35 -> 32178.222 | L33: =K35 -> 73232.175 | M33: =L35 -> 115957 | N33: =M35 -> 153769.27
D34: Cash for the Period | E34: [₦ 0'000] | J34: =J31+J25+J22 -> 32178.222 | K34: =K31+K25+K22 -> 41053.953 | L34: =L31+L25+L22 -> 42724.822 | M34: =M31+M25+M22 -> 37812.276 | N34: =N31+N25+N22 -> 31289.428
D35: Ending Cash Balance | E35: [₦ 0'000] | J35: =J33+J34 -> 32178.222 | K35: =K33+K34 -> 73232.175 | L35: =L33+L34 -> 115957 | M35: =M33+M34 -> 153769.27 | N35: =N33+N34 -> 185058.7

Sheet BS
B2: =Company_Name -> Tage Corp | N2: Menu
C3: ='Model Guide'!D27 -> Balance Sheet
D4: Model Scenerio
D5: Model Balance Check | H5: Start Date | J5: =I6+Ctrl_1 -> 45658 | K5: =J6+Ctrl_1 -> 46023 | L5: =K6+Ctrl_1 -> 46388 | M5: =L6+Ctrl_1 -> 46753 | N5: =M6+Ctrl_1 -> 47119
H6: End Date | I6: =EOMONTH(J6,- Ctrl_12) -> 45657 | J6: =EOMONTH(K6,- Ctrl_12) -> 46022 | K6: =EOMONTH(L6,- Ctrl_12) -> 46387 | L6: =EOMONTH(M6,- Ctrl_12) -> 46752 | M6: =EOMONTH(N6,- Ctrl_12) -> 47118 | N6: =Model_Period_End -> 47483
H7: Year | I7: =YEAR(I6) -> 2024 | J7: =YEAR(J6) -> 2025 | K7: =YEAR(K6) -> 2026 | L7: =YEAR(L6) -> 2027 | M7: =YEAR(M6) -> 2028 | N7: =YEAR(N6) -> 2029
G8: Check | J8: =IF(J21=J35, "Balance",J21-J35) -> Balance | K8: =IF(K21=K35, "Balance",K21-K35) -> Balance | L8: =IF(L21=L35, "Balance",L21-L35) -> Balance | M8: =IF(M21=M35, "Balance",M21-M35) -> Balance | N8: =IF(N21=N35, "Balance",N21-N35) -> Balance
D9: Descriptions | E9: Units | F9: Input/Linked | H9: Row Total | I9: Forecast | J9: Forecast | K9: Forecast | L9: Forecast | M9: Forecast | N9: Forecast
I10: =I7-$I$7 -> 0 | J10: =J7-$I$7 -> 1 | K10: =K7-$I$7 -> 2 | L10: =L7-$I$7 -> 3 | M10: =M7-$I$7 -> 4 | N10: =N7-$I$7 -> 5
C11: Assets
D12: Non Current Assets (NCA)
D13: Net PPE | E13: [₦'000] | J13: =Cal!J171/Divisor -> 6000 | K13: =Cal!K171/Divisor -> 5580 | L13: =Cal!L171/Divisor -> 4878 | M13: =Cal!M171/Divisor -> 5565.4 | N13: =Cal!N171/Divisor -> 6269.02
D14: Total NCA | E14: [₦'000] | J14: =SUM(J13) -> 6000 | K14: =SUM(K13) -> 5580 | L14: =SUM(L13) -> 4878 | M14: =SUM(M13) -> 5565.4 | N14: =SUM(N13) -> 6269.02
D15: Current Assets (CA)
D16: Inventories | E16: [₦'000] | J16: =Cal!J117/Divisor -> 5054.7945 | K16: =Cal!K117/Divisor -> 5415.2014 | L16: =Cal!L117/Divisor -> 7253.3719 | M16: =Cal!M117/Divisor -> 11159.001 | N16: =Cal!N117/Divisor -> 15955.217
D17: Trade Recievable | E17: [₦'000] | J17: =Cal!J118/Divisor -> 13972.603 | K17: =Cal!K118/Divisor -> 15223.32 | L17: =Cal!L118/Divisor -> 16901.141 | M17: =Cal!M118/Divisor -> 19161.938 | N17: =Cal!N118/Divisor -> 22281.244
D18: Prepayment | E18: [₦'000] | J18: =Cal!J119/Divisor -> 1088.2192 | K18: =Cal!K119/Divisor -> 773.80989 | L18: =Cal!L119/Divisor -> 881.30959 | M18: =Cal!M119/Divisor -> 809.67131 | N18: =Cal!N119/Divisor -> 885.47581
D19: Cash & Cash equivalent | E19: [₦'000] | J19: =CF!J35 -> 32178.222 | K19: =CF!K35 -> 73232.175 | L19: =CF!L35 -> 115957 | M19: =CF!M35 -> 153769.27 | N19: =CF!N35 -> 185058.7
D20: Total CA | E20: [₦'000] | J20: =SUM(J16:J19) -> 52293.839 | K20: =SUM(K16:K19) -> 94644.506 | L20: =SUM(L16:L19) -> 140992.82 | M20: =SUM(M16:M19) -> 184899.88 | N20: =SUM(N16:N19) -> 224180.64
D21: Total Assets | E21: [₦'000] | J21: =J20+J14 -> 58293.839 | K21: =K20+K14 -> 100224.51 | L21: =L20+L14 -> 145870.82 | M21: =M20+M14 -> 190465.28 | N21: =N20+N14 -> 230449.66
C22: Liabilities
D23: Non Current Liabilities (NCL)
D24: Long Term Loan | E24: [₦'000] | J24: =Cal!J138/Divisor -> 4859.6843 | K24: =Cal!K138/Divisor -> 1295.4259 | L24: =Cal!L138/Divisor -> 0 | M24: =Cal!M138/Divisor -> 0 | N24: =Cal!N138/Divisor -> 0
D25: Total NCL | E25: [₦'000] | J25: =SUM(J24) -> 4859.6843 | K25: =SUM(K24) -> 1295.4259 | L25: =SUM(L24) -> 0 | M25: =SUM(M24) -> 0 | N25: =SUM(N24) -> 0
D26: Current Liabilities (CL)
D27: Trade Payables | E27: [₦'000] | J27: =Cal!J122/Divisor -> 4043.8356 | K27: =Cal!K122/Divisor -> 4332.1611 | L27: =Cal!L122/Divisor -> 5802.6975 | M27: =Cal!M122/Divisor -> 8927.2009 | N27: =Cal!N122/Divisor -> 12764.173
D28: Accurals & Other Liabilities | E28: [₦'000] | J28: =Cal!J123/Divisor -> 1450.9589 | K28: =Cal!K123/Divisor -> 1031.7465 | L28: =Cal!L123/Divisor -> 1175.0795 | M28: =Cal!M123/Divisor -> 1079.5617 | N28: =Cal!N123/Divisor -> 1180.6344
D29: Total CL | E29: [₦'000] | J29: =SUM(J27:J28) -> 5494.7945 | K29: =SUM(K27:K28) -> 5363.9076 | L29: =SUM(L27:L28) -> 6977.777 | M29: =SUM(M27:M28) -> 10006.763 | N29: =SUM(N27:N28) -> 13944.808
D30: Total Liabilities | E30: [₦'000] | J30: =SUM(J29+J25) -> 10354.479 | K30: =SUM(K29+K25) -> 6659.3335 | L30: =SUM(L29+L25) -> 6977.777 | M30: =SUM(M29+M25) -> 10006.763 | N30: =SUM(N29+N25) -> 13944.808
C31: Equity
D32: Share Capital | E32: [₦'000] | J32: =Cal!$J$143/Divisor -> 12000 | K32: =Cal!$J$143/Divisor -> 12000 | L32: =Cal!$J$143/Divisor -> 12000 | M32: =Cal!$J$143/Divisor -> 12000 | N32: =Cal!$J$143/Divisor -> 12000
D33: Retained Earnings | E33: [₦'000] | J33: =Cal!J156/Divisor -> 35939.36 | K33: =Cal!K156/Divisor -> 81565.173 | L33: =Cal!L156/Divisor -> 126893.04 | M33: =Cal!M156/Divisor -> 168458.52 | N33: =Cal!N156/Divisor -> 204504.85
D34: Total Equity | E34: [₦'000] | J34: =SUM(J32:J33) -> 47939.36 | K34: =SUM(K32:K33) -> 93565.173 | L34: =SUM(L32:L33) -> 138893.04 | M34: =SUM(M32:M33) -> 180458.52 | N34: =SUM(N32:N33) -> 216504.85
D35: Total Equity & Liabilities | E35: [₦'000] | J35: =J34+J30 -> 58293.839 | K35: =K34+K30 -> 100224.51 | L35: =L34+L30 -> 145870.82 | M35: =M34+M30 -> 190465.28 | N35: =N34+N30 -> 230449.66
D38: Model Check
J39: =J21-J35 -> 0 | K39: =K21-K35 -> 0 | L39: =L21-L35 -> 0 | M39: =M21-M35 -> 0 | N39: =N21-N35 -> 0
J40: =J35=J21 -> TRUE | K40: =K35=K21 -> TRUE | L40: =L35=L21 -> TRUE | M40: =M35=M21 -> TRUE | N40: =N35=N21 -> TRUE

Sheet Scenerio
B2: =Company_Name -> Tage Corp | N2: Menu
C3: ='Model Guide'!D29 -> Analysis
D4: Model Scenerio
D5: Model Balance Check | H5: Start Date | J5: =I6+Ctrl_1 -> 45658 | K5: =J6+Ctrl_1 -> 46023 | L5: =K6+Ctrl_1 -> 46388 | M5: =L6+Ctrl_1 -> 46753 | N5: =M6+Ctrl_1 -> 47119
H6: End Date | I6: =EOMONTH(J6,- Ctrl_12) -> 45657 | J6: =EOMONTH(K6,- Ctrl_12) -> 46022 | K6: =EOMONTH(L6,- Ctrl_12) -> 46387 | L6: =EOMONTH(M6,- Ctrl_12) -> 46752 | M6: =EOMONTH(N6,- Ctrl_12) -> 47118 | N6: =Model_Period_End -> 47483
H7: Year | I7: =YEAR(I6) -> 2024 | J7: =YEAR(J6) -> 2025 | K7: =YEAR(K6) -> 2026 | L7: =YEAR(L6) -> 2027 | M7: =YEAR(M6) -> 2028 | N7: =YEAR(N6) -> 2029
D8: Descriptions | E8: Units | F8: Input/Linked | H8: Row Total | I8: Forecast | J8: Forecast | K8: Forecast | L8: Forecast | M8: Forecast | N8: Forecast
I9: =I7-$I$7 -> 0 | J9: =J7-$I$7 -> 1 | K9: =K7-$I$7 -> 2 | L9: =L7-$I$7 -> 3 | M9: =M7-$I$7 -> 4 | N9: =N7-$I$7 -> 5
F10: 2 | G10: switch
D11: 1 | E11: Best Case
D12: 2 | E12: Base Case | G12: List
D13: 3 | E13: Worst Case
E16: Inflation | J16: =CHOOSE(switch,J17,J18,J19) -> 0.3003 | K16: =CHOOSE(switch,K17,K18,K19) -> 0.2503 | L16: =CHOOSE(switch,L17,L18,L19) -> 0.2 | M16: =CHOOSE(switch,M17,M18,M19) -> 0.1 | N16: =CHOOSE(switch,N17,N18,N19) -> 0.1
E17: =E11 -> Best Case | J17: 0.2853 | K17: 0.2353 | L17: 0.185 | M17: 0.085 | N17: 0.085
E18: =E12 -> Base Case | J18: 0.3003 | K18: 0.2503 | L18: 0.2 | M18: 0.1 | N18: 0.1
E19: =E13 -> Worst Case | J19: 0.3203 | K19: 0.2703 | L19: 0.22 | M19: 0.12 | N19: 0.12
E22: Quantity | J22: =CHOOSE(switch,J23,J24,J25) -> 0.0713 | K22: =CHOOSE(switch,K23,K24,K25) -> 0.0713 | L22: =CHOOSE(switch,L23,L24,L25) -> 0.0713 | M22: =CHOOSE(switch,M23,M24,M25) -> 0.0713 | N22: =CHOOSE(switch,N23,N24,N25) -> 0.0713
E23: =E17 -> Best Case | J23: 0.0963 | K23: 0.0963 | L23: 0.0963 | M23: 0.0963 | N23: 0.0963
E24: =E18 -> Base Case | J24: 0.0713 | K24: 0.0713 | L24: 0.0713 | M24: 0.0713 | N24: 0.0713
E25: =E19 -> Worst Case | J25: 0.0563 | K25: 0.0563 | L25: 0.0563 | M25: 0.0563 | N25: 0.0563

Sheet Analysis
B2: =Company_Name -> Tage Corp | N2: Menu
C3: ='Model Guide'!D29 -> Analysis
D4: Model Scenerio
D5: Model Balance Check | H5: Start Date | J5: =I6+Ctrl_1 -> 45658 | K5: =J6+Ctrl_1 -> 46023 | L5: =K6+Ctrl_1 -> 46388 | M5: =L6+Ctrl_1 -> 46753 | N5: =M6+Ctrl_1 -> 47119
H6: End Date | I6: =EOMONTH(J6,- Ctrl_12) -> 45657 | J6: =EOMONTH(K6,- Ctrl_12) -> 46022 | K6: =EOMONTH(L6,- Ctrl_12) -> 46387 | L6: =EOMONTH(M6,- Ctrl_12) -> 46752 | M6: =EOMONTH(N6,- Ctrl_12) -> 47118 | N6: =Model_Period_End -> 47483
H7: Year | I7: =YEAR(I6) -> 2024 | J7: =YEAR(J6) -> 2025 | K7: =YEAR(K6) -> 2026 | L7: =YEAR(L6) -> 2027 | M7: =YEAR(M6) -> 2028 | N7: =YEAR(N6) -> 2029
D8: Descriptions | E8: Units | F8: Input/Linked | H8: Row Total | I8: Forecast | J8: Forecast | K8: Forecast | L8: Forecast | M8: Forecast | N8: Forecast
I9: =I7-$I$7 -> 0 | J9: =J7-$I$7 -> 1 | K9: =K7-$I$7 -> 2 | L9: =L7-$I$7 -> 3 | M9: =M7-$I$7 -> 4 | N9: =N7-$I$7 -> 5

Sheet Valuation
B2: =Company_Name -> Tage Corp | N2: Menu
C3: ='Model Guide'!D30 -> Valuation
D4: Model Scenerio
D5: Model Balance Check | H5: Start Date | J5: =I6+Ctrl_1 -> 45658 | K5: =J6+Ctrl_1 -> 46023 | L5: =K6+Ctrl_1 -> 46388 | M5: =L6+Ctrl_1 -> 46753 | N5: =M6+Ctrl_1 -> 47119
H6: End Date | I6: =EOMONTH(J6,- Ctrl_12) -> 45657 | J6: =EOMONTH(K6,- Ctrl_12) -> 46022 | K6: =EOMONTH(L6,- Ctrl_12) -> 46387 | L6: =EOMONTH(M6,- Ctrl_12) -> 46752 | M6: =EOMONTH(N6,- Ctrl_12) -> 47118 | N6: =Model_Period_End -> 47483
H7: Year | I7: =YEAR(I6) -> 2024 | J7: =YEAR(J6) -> 2025 | K7: =YEAR(K6) -> 2026 | L7: =YEAR(L6) -> 2027 | M7: =YEAR(M6) -> 2028 | N7: =YEAR(N6) -> 2029
D8: Descriptions | E8: Units | F8: Input/Linked | H8: Row Total | I8: Forecast | J8: Forecast | K8: Forecast | L8: Forecast | M8: Forecast | N8: Forecast
I9: =I7-$I$7 -> 0 | J9: =J7-$I$7 -> 1 | K9: =K7-$I$7 -> 2 | L9: =L7-$I$7 -> 3 | M9: =M7-$I$7 -> 4 | N9: =N7-$I$7 -> 5

Sheet Temp
B2: =Company_Name -> Tage Corp | N2: Menu
C3: Template
D4: Model Scenerio
D5: Model Balance Check | H5: Start Date | J5: =I6+Ctrl_1 -> 45658 | K5: =J6+Ctrl_1 -> 46023 | L5: =K6+Ctrl_1 -> 46388 | M5: =L6+Ctrl_1 -> 46753 | N5: =M6+Ctrl_1 -> 47119
H6: End Date | I6: =EOMONTH(J6,- Ctrl_12) -> 45657 | J6: =EOMONTH(K6,- Ctrl_12) -> 46022 | K6: =EOMONTH(L6,- Ctrl_12) -> 46387 | L6: =EOMONTH(M6,- Ctrl_12) -> 46752 | M6: =EOMONTH(N6,- Ctrl_12) -> 47118 | N6: =Model_Period_End -> 47483
H7: Year | I7: =YEAR(I6) -> 2024 | J7: =YEAR(J6) -> 2025 | K7: =YEAR(K6) -> 2026 | L7: =YEAR(L6) -> 2027 | M7: =YEAR(M6) -> 2028 | N7: =YEAR(N6) -> 2029
D8: Descriptions | H8: Row Total | I8: Forecast | J8: Forecast | K8: Forecast | L8: Forecast | M8: Forecast | N8: Forecast
I9: =I7-$I$7 -> 0 | J9: =J7-$I$7 -> 1 | K9: =K7-$I$7 -> 2 | L9: =L7-$I$7 -> 3 | M9: =M7-$I$7 -> 4 | N9: =N7-$I$7 -> 5
